Workbook

Sheet Dashboard
A1: DASHBOARD · CONTROL DE DINERO PERSONAL
B2: Saldo inicial | C2: 500 | E2: Mes actual | F2: Objetivo: detectar fugas y ajustar rápido
B3: Saldo actual | C3: =LOOKUP(2,1/(MOVIMIENTOS!I6:I500<>""),MOVIMIENTOS!I6:I500) -> 1217.1
B4: Ingresos del mes | C4: =SUMIFS(MOVIMIENTOS!$H$6:$H$500,MOVIMIENTOS!$D$6:$D$500,"Ingreso",MOVIMIENTOS!$C$6:$C$500,">="&EOMONTH(TODAY(),-1)+1,MOVIMIENTOS!$C$6:$C$500,"<="&EOMONTH(TODAY(),0)) -> 0 | E4: Categoría | F4: Gasto mes | G4: Presupuesto | H4: Diferencia
B5: Gastos del mes | C5: =SUMIFS(MOVIMIENTOS!$H$6:$H$500,MOVIMIENTOS!$D$6:$D$500,"Gasto",MOVIMIENTOS!$C$6:$C$500,">="&EOMONTH(TODAY(),-1)+1,MOVIMIENTOS!$C$6:$C$500,"<="&EOMONTH(TODAY(),0)) -> 651.5 | E5: Alimentación | F5: =SUMIFS(MOVIMIENTOS!$H$6:$H$500,MOVIMIENTOS!$D$6:$D$500,"Gasto",MOVIMIENTOS!$E$6:$E$500,E5,MOVIMIENTOS!$C$6:$C$500,">="&EOMONTH(TODAY(),-1)+1,MOVIMIENTOS!$C$6:$C$500,"<="&EOMONTH(TODAY(),0)) -> 113 | G5: =IFERROR(VLOOKUP(E5,PRESUPUESTO!$B$4:$D$50,2,FALSE()),0) -> 600 | H5: =G5-F5 -> 487
B6: Flujo neto | C6: =C4-C5 -> -651.5 | E6: Vivienda | F6: =SUMIFS(MOVIMIENTOS!$H$6:$H$500,MOVIMIENTOS!$D$6:$D$500,"Gasto",MOVIMIENTOS!$E$6:$E$500,E6,MOVIMIENTOS!$C$6:$C$500,">="&EOMONTH(TODAY(),-1)+1,MOVIMIENTOS!$C$6:$C$500,"<="&EOMONTH(TODAY(),0)) -> 35.5 | G6: =IFERROR(VLOOKUP(E6,PRESUPUESTO!$B$4:$D$50,2,FALSE()),0) -> 550 | H6: =G6-F6 -> 514.5
B7: % Gasto / Ingreso | C7: =IFERROR(C5/C4,0) -> 0 | E7: Transporte | F7: =SUMIFS(MOVIMIENTOS!$H$6:$H$500,MOVIMIENTOS!$D$6:$D$500,"Gasto",MOVIMIENTOS!$E$6:$E$500,E7,MOVIMIENTOS!$C$6:$C$500,">="&EOMONTH(TODAY(),-1)+1,MOVIMIENTOS!$C$6:$C$500,"<="&EOMONTH(TODAY(),0)) -> 0 | G7: =IFERROR(VLOOKUP(E7,PRESUPUESTO!$B$4:$D$50,2,FALSE()),0) -> 0 | H7: =G7-F7 -> 0
B8: % Ahorro | C8: =IFERROR(1-C7,0) -> 1 | E8: Vehículo | F8: =SUMIFS(MOVIMIENTOS!$H$6:$H$500,MOVIMIENTOS!$D$6:$D$500,"Gasto",MOVIMIENTOS!$E$6:$E$500,E8,MOVIMIENTOS!$C$6:$C$500,">="&EOMONTH(TODAY(),-1)+1,MOVIMIENTOS!$C$6:$C$500,"<="&EOMONTH(TODAY(),0)) -> 120 | G8: =IFERROR(VLOOKUP(E8,PRESUPUESTO!$B$4:$D$50,2,FALSE()),0) -> 0 | H8: =G8-F8 -> -120
E9: Deuda | F9: =SUMIFS(MOVIMIENTOS!$H$6:$H$500,MOVIMIENTOS!$D$6:$D$500,"Gasto",MOVIMIENTOS!$E$6:$E$500,E9,MOVIMIENTOS!$C$6:$C$500,">="&EOMONTH(TODAY(),-1)+1,MOVIMIENTOS!$C$6:$C$500,"<="&EOMONTH(TODAY(),0)) -> 300 | G9: =IFERROR(VLOOKUP(E9,PRESUPUESTO!$B$4:$D$50,2,FALSE()),0) -> 1300 | H9: =G9-F9 -> 1000
E10: Salud | F10: =SUMIFS(MOVIMIENTOS!$H$6:$H$500,MOVIMIENTOS!$D$6:$D$500,"Gasto",MOVIMIENTOS!$E$6:$E$500,E10,MOVIMIENTOS!$C$6:$C$500,">="&EOMONTH(TODAY(),-1)+1,MOVIMIENTOS!$C$6:$C$500,"<="&EOMONTH(TODAY(),0)) -> 0 | G10: =IFERROR(VLOOKUP(E10,PRESUPUESTO!$B$4:$D$50,2,FALSE()),0) -> 0 | H10: =G10-F10 -> 0
E11: Cuidado Personal | F11: =SUMIFS(MOVIMIENTOS!$H$6:$H$500,MOVIMIENTOS!$D$6:$D$500,"Gasto",MOVIMIENTOS!$E$6:$E$500,E11,MOVIMIENTOS!$C$6:$C$500,">="&EOMONTH(TODAY(),-1)+1,MOVIMIENTOS!$C$6:$C$500,"<="&EOMONTH(TODAY(),0)) -> 16 | G11: =IFERROR(VLOOKUP(E11,PRESUPUESTO!$B$4:$D$50,2,FALSE()),0) -> 0 | H11: =G11-F11 -> -16
E12: Indumentaria | F12: =SUMIFS(MOVIMIENTOS!$H$6:$H$500,MOVIMIENTOS!$D$6:$D$500,"Gasto",MOVIMIENTOS!$E$6:$E$500,E12,MOVIMIENTOS!$C$6:$C$500,">="&EOMONTH(TODAY(),-1)+1,MOVIMIENTOS!$C$6:$C$500,"<="&EOMONTH(TODAY(),0)) -> 0 | G12: =IFERROR(VLOOKUP(E12,PRESUPUESTO!$B$4:$D$50,2,FALSE()),0) -> 0 | H12: =G12-F12 -> 0
E13: Educación | F13: =SUMIFS(MOVIMIENTOS!$H$6:$H$500,MOVIMIENTOS!$D$6:$D$500,"Gasto",MOVIMIENTOS!$E$6:$E$500,E13,MOVIMIENTOS!$C$6:$C$500,">="&EOMONTH(TODAY(),-1)+1,MOVIMIENTOS!$C$6:$C$500,"<="&EOMONTH(TODAY(),0)) -> 0 | G13: =IFERROR(VLOOKUP(E13,PRESUPUESTO!$B$4:$D$50,2,FALSE()),0) -> 0 | H13: =G13-F13 -> 0
E14: Trabajo / Negocio | F14: =SUMIFS(MOVIMIENTOS!$H$6:$H$500,MOVIMIENTOS!$D$6:$D$500,"Gasto",MOVIMIENTOS!$E$6:$E$500,E14,MOVIMIENTOS!$C$6:$C$500,">="&EOMONTH(TODAY(),-1)+1,MOVIMIENTOS!$C$6:$C$500,"<="&EOMONTH(TODAY(),0)) -> 0 | G14: =IFERROR(VLOOKUP(E14,PRESUPUESTO!$B$4:$D$50,2,FALSE()),0) -> 0 | H14: =G14-F14 -> 0
E15: Ocio | F15: =SUMIFS(MOVIMIENTOS!$H$6:$H$500,MOVIMIENTOS!$D$6:$D$500,"Gasto",MOVIMIENTOS!$E$6:$E$500,E15,MOVIMIENTOS!$C$6:$C$500,">="&EOMONTH(TODAY(),-1)+1,MOVIMIENTOS!$C$6:$C$500,"<="&EOMONTH(TODAY(),0)) -> 0 | G15: =IFERROR(VLOOKUP(E15,PRESUPUESTO!$B$4:$D$50,2,FALSE()),0) -> 0 | H15: =G15-F15 -> 0
E16: Ingresos | F16: =SUMIFS(MOVIMIENTOS!$H$6:$H$500,MOVIMIENTOS!$D$6:$D$500,"Gasto",MOVIMIENTOS!$E$6:$E$500,E16,MOVIMIENTOS!$C$6:$C$500,">="&EOMONTH(TODAY(),-1)+1,MOVIMIENTOS!$C$6:$C$500,"<="&EOMONTH(TODAY(),0)) -> 0 | G16: =IFERROR(VLOOKUP(E16,PRESUPUESTO!$B$4:$D$50,2,FALSE()),0) -> 0 | H16: =G16-F16 -> 0
E17: Otros | F17: =SUMIFS(MOVIMIENTOS!$H$6:$H$500,MOVIMIENTOS!$D$6:$D$500,"Gasto",MOVIMIENTOS!$E$6:$E$500,E17,MOVIMIENTOS!$C$6:$C$500,">="&EOMONTH(TODAY(),-1)+1,MOVIMIENTOS!$C$6:$C$500,"<="&EOMONTH(TODAY(),0)) -> 67 | G17: =IFERROR(VLOOKUP(E17,PRESUPUESTO!$B$4:$D$50,2,FALSE()),0) -> 0 | H17: =G17-F17 -> -67

Sheet MOVIMIENTOS
C5: Fecha | D5: Tipo | E5: Categoría | F5: Subcategoría | G5: Descripción / detalle | H5: Monto | I5: Saldo | J5: Medio de pago | K5: Notas
C6: 46140 | D6: Gasto | E6: Otros | F6: Trámites / Legalizaciones | G6: Legalizacion documento Emb. Par | H6: 106.3 | I6: =IF(C6="","",Dashboard!$C$2+IF(D6="Ingreso",H6,-H6)) -> 393.7 | J6: Yape / Plin | L6: =SUMIF($E:$E,K6,$G:$G) -> 0
C7: 46140 | D7: Gasto | E7: Otros | F7: Trámites / Legalizaciones | G7: Apostilla | H7: 31 | I7: =IF(C7="","",I6+IF(D7="Ingreso",H7,-H7)) -> 362.7 | J7: Yape / Plin | L7: =SUMIF($E:$E,K7,$G:$G) -> 0
C8: 46140 | D8: Gasto | E8: Alimentación | F8: Desayuno | G8: Desayuno | H8: 18 | I8: =IF(C8="","",I7+IF(D8="Ingreso",H8,-H8)) -> 344.7 | L8: =SUMIF($E:$E,K8,$G:$G) -> 0
C9: =C7 -> 46140 | D9: Gasto | E9: Alimentación | F9: Almuerzo | G9: Almuerzo | H9: 35 | I9: =IF(C9="","",I8+IF(D9="Ingreso",H9,-H9)) -> 309.7
C10: =C8 -> 46140 | D10: Gasto | E10: Transporte | F10: Otros transporte | H10: 10 | I10: =IF(C10="","",I9+IF(D10="Ingreso",H10,-H10)) -> 299.7
C11: =C9 -> 46140 | D11: Gasto | E11: Cuidado Personal | F11: Shampoo / Higiene | G11: Shampoo | H11: 3 | I11: =IF(C11="","",I10+IF(D11="Ingreso",H11,-H11)) -> 296.7
C12: =C10 -> 46140 | D12: Gasto | E12: Otros | F12: Otros | G12: Por informacion de documentos | H12: 15 | I12: =IF(C12="","",I11+IF(D12="Ingreso",H12,-H12)) -> 281.7
C13: =C11 -> 46140 | D13: Gasto | E13: Alimentación | F13: Snacks / Golosinas | G13: Galletas | H13: 8 | I13: =IF(C13="","",I12+IF(D13="Ingreso",H13,-H13)) -> 273.7
C14: =C12 -> 46140 | D14: Gasto | E14: Vehículo | F14: Repuestos | G14: Fusibles | H14: 11 | I14: =IF(C14="","",I13+IF(D14="Ingreso",H14,-H14)) -> 262.7
C15: =C13 -> 46140 | D15: Gasto | E15: Transporte | F15: Peajes | G15: Peajes | H15: 32.2 | I15: =IF(C15="","",I14+IF(D15="Ingreso",H15,-H15)) -> 230.5
C16: 46140 | D16: Gasto | E16: Otros | F16: Migraciones | G16: Migraciones | H16: 161.4 | I16: =IF(C16="","",I15+IF(D16="Ingreso",H16,-H16)) -> 69.1
C17: 46140 | D17: Gasto | E17: Alimentación | F17: Cena | G17: Cena | H17: 26 | I17: =IF(C17="","",I16+IF(D17="Ingreso",H17,-H17)) -> 43.1
C18: 46140 | D18: Gasto | E18: Salud | F18: Farmacia | G18: Farmacia, anis y otros | H18: 14.5 | I18: =IF(C18="","",I17+IF(D18="Ingreso",H18,-H18)) -> 28.6
C19: 46141 | D19: Gasto | E19: Alimentación | F19: Desayuno | G19: Desayuno | H19: 6 | I19: =IF(C19="","",I18+IF(D19="Ingreso",H19,-H19)) -> 22.6
C20: 46141 | D20: Gasto | E20: Transporte | F20: Otros transporte | H20: 5.5 | I20: =IF(C20="","",I19+IF(D20="Ingreso",H20,-H20)) -> 17.1
C21: 46141 | D21: Gasto | E21: Otros | F21: Otros | G21: Desconoce | H21: 6.1 | I21: =IF(C21="","",I20+IF(D21="Ingreso",H21,-H21)) -> 11
C22: 46141 | D22: Ingreso | E22: Ingresos | F22: Trabajo extra | G22: Trabajo | H22: 2000 | I22: =IF(C22="","",I21+IF(D22="Ingreso",H22,-H22)) -> 2011
C23: 46141 | D23: Gasto | E23: Alimentación | F23: Cena | G23: Cena | H23: 41 | I23: =IF(C23="","",I22+IF(D23="Ingreso",H23,-H23)) -> 1970
C24: 46141 | D24: Gasto | E24: Cuidado Personal | F24: Aseo personal | G24: Toallas | H24: 8.4 | I24: =IF(C24="","",I23+IF(D24="Ingreso",H24,-H24)) -> 1961.6
C25: 46142 | D25: Gasto | E25: Alimentación | F25: Almuerzo | G25: Almuerzo | H25: 39 | I25: =IF(C25="","",I24+IF(D25="Ingreso",H25,-H25)) -> 1922.6
C26: 46142 | D26: Gasto | E26: Alimentación | F26: Desayuno | G26: desayuno | H26: 24 | I26: =IF(C26="","",I25+IF(D26="Ingreso",H26,-H26)) -> 1898.6
C27: 46142 | D27: Gasto | E27: Vehículo | F27: Accesorios | G27: Portacelular | H27: 30 | I27: =IF(C27="","",I26+IF(D27="Ingreso",H27,-H27)) -> 1868.6
C28: 46143 | D28: Gasto | E28: Vivienda | F28: Equipamiento hogar | G28: Termo | H28: 35.5 | I28: =IF(C28="","",I27+IF(D28="Ingreso",H28,-H28)) -> 1833.1
C29: 46143 | D29: Gasto | E29: Otros | F29: Otros | G29: Parlante y cable | H29: 67 | I29: =IF(C29="","",I28+IF(D29="Ingreso",H29,-H29)) -> 1766.1
C30: 46143 | D30: Gasto | E30: Deuda | F30: Alquiler galpón | G30: Alquiler galpon | H30: 300 | I30: =IF(C30="","",I29+IF(D30="Ingreso",H30,-H30)) -> 1466.1
C31: 46143 | D31: Gasto | E31: Vehículo | F31: Combustible | G31: Combustible | H31: 120 | I31: =IF(C31="","",I30+IF(D31="Ingreso",H31,-H31)) -> 1346.1
C32: 46144 | D32: Gasto | E32: Alimentación | F32: Otros alimentación | G32: De dias 1,2 | H32: 70.4 | I32: =IF(C32="","",I31+IF(D32="Ingreso",H32,-H32)) -> 1275.7
... C35: 46144 | D35: Gasto | E35: Alimentación | F35: Otros alimentación | G35: otros | H35: 4 | I35: =IF(C35="","",I34+IF(D35="Ingreso",H35,-H35)) -> 1217.1
H36: =H35-G36 -> 4 | I36: =IF(C36="","",I35+IF(D36="Ingreso",H36,-H36))
H37: =H36-G37 -> 4 | I37: =IF(C37="","",I36+IF(D37="Ingreso",H37,-H37))
H38: =H37-G38 -> 4 | I38: =IF(C38="","",I37+IF(D38="Ingreso",H38,-H38))
H39: =H38-G39 -> 4 | I39: =IF(C39="","",I38+IF(D39="Ingreso",H39,-H39))
H40: =H39-G40 -> 4 | I40: =IF(C40="","",I39+IF(D40="Ingreso",H40,-H40))
H41: =H40-G41 -> 4 | I41: =IF(C41="","",I40+IF(D41="Ingreso",H41,-H41))
H42: =H41-G42 -> 4 | I42: =IF(C42="","",I41+IF(D42="Ingreso",H42,-H42))
H43: =H42-G43 -> 4 | I43: =IF(C43="","",I42+IF(D43="Ingreso",H43,-H43))
H44: =H43-G44 -> 4 | I44: =IF(C44="","",I43+IF(D44="Ingreso",H44,-H44))
H45: =H44-G45 -> 4 | I45: =IF(C45="","",I44+IF(D45="Ingreso",H45,-H45))
H46: =H45-G46 -> 4 | I46: =IF(C46="","",I45+IF(D46="Ingreso",H46,-H46))
...

Sheet RESUMEN
A1: RESUMEN MENSUAL Y POR CATEGORÍA
B3: Mes | C3: Ingresos | D3: Gastos | E3: Flujo neto | F3: Saldo cierre | G3: Estado
B4: =EOMONTH(TODAY(),-11)+1 -> 45839 | C4: =SUMIFS(MOVIMIENTOS!$H$6:$H$500,MOVIMIENTOS!$D$6:$D$500,"Ingreso",MOVIMIENTOS!$C$6:$C$500,">="&B4,MOVIMIENTOS!$C$6:$C$500,"<"&EDATE(B4,1)) -> 0 | D4: =SUMIFS(MOVIMIENTOS!$H$6:$H$500,MOVIMIENTOS!$D$6:$D$500,"Gasto",MOVIMIENTOS!$C$6:$C$500,">="&B4,MOVIMIENTOS!$C$6:$C$500,"<"&EDATE(B4,1)) -> 0 | E4: =C4-D4 -> 0 | F4: =Dashboard!$C$2+SUM($E$4:E4) -> 500 | G4: =IF(E4<0,"Déficit","OK") -> OK
B5: =EOMONTH(TODAY(),-10)+1 -> 45870 | C5: =SUMIFS(MOVIMIENTOS!$H$6:$H$500,MOVIMIENTOS!$D$6:$D$500,"Ingreso",MOVIMIENTOS!$C$6:$C$500,">="&B5,MOVIMIENTOS!$C$6:$C$500,"<"&EDATE(B5,1)) -> 0 | D5: =SUMIFS(MOVIMIENTOS!$H$6:$H$500,MOVIMIENTOS!$D$6:$D$500,"Gasto",MOVIMIENTOS!$C$6:$C$500,">="&B5,MOVIMIENTOS!$C$6:$C$500,"<"&EDATE(B5,1)) -> 0 | E5: =C5-D5 -> 0 | F5: =Dashboard!$C$2+SUM($E$4:E5) -> 500 | G5: =IF(E5<0,"Déficit","OK") -> OK
B6: =EOMONTH(TODAY(),-9)+1 -> 45901 | C6: =SUMIFS(MOVIMIENTOS!$H$6:$H$500,MOVIMIENTOS!$D$6:$D$500,"Ingreso",MOVIMIENTOS!$C$6:$C$500,">="&B6,MOVIMIENTOS!$C$6:$C$500,"<"&EDATE(B6,1)) -> 0 | D6: =SUMIFS(MOVIMIENTOS!$H$6:$H$500,MOVIMIENTOS!$D$6:$D$500,"Gasto",MOVIMIENTOS!$C$6:$C$500,">="&B6,MOVIMIENTOS!$C$6:$C$500,"<"&EDATE(B6,1)) -> 0 | E6: =C6-D6 -> 0 | F6: =Dashboard!$C$2+SUM($E$4:E6) -> 500 | G6: =IF(E6<0,"Déficit","OK") -> OK
B7: =EOMONTH(TODAY(),-8)+1 -> 45931 | C7: =SUMIFS(MOVIMIENTOS!$H$6:$H$500,MOVIMIENTOS!$D$6:$D$500,"Ingreso",MOVIMIENTOS!$C$6:$C$500,">="&B7,MOVIMIENTOS!$C$6:$C$500,"<"&EDATE(B7,1)) -> 0 | D7: =SUMIFS(MOVIMIENTOS!$H$6:$H$500,MOVIMIENTOS!$D$6:$D$500,"Gasto",MOVIMIENTOS!$C$6:$C$500,">="&B7,MOVIMIENTOS!$C$6:$C$500,"<"&EDATE(B7,1)) -> 0 | E7: =C7-D7 -> 0 | F7: =Dashboard!$C$2+SUM($E$4:E7) -> 500 | G7: =IF(E7<0,"Déficit","OK") -> OK
B8: =EOMONTH(TODAY(),-7)+1 -> 45962 | C8: =SUMIFS(MOVIMIENTOS!$H$6:$H$500,MOVIMIENTOS!$D$6:$D$500,"Ingreso",MOVIMIENTOS!$C$6:$C$500,">="&B8,MOVIMIENTOS!$C$6:$C$500,"<"&EDATE(B8,1)) -> 0 | D8: =SUMIFS(MOVIMIENTOS!$H$6:$H$500,MOVIMIENTOS!$D$6:$D$500,"Gasto",MOVIMIENTOS!$C$6:$C$500,">="&B8,MOVIMIENTOS!$C$6:$C$500,"<"&EDATE(B8,1)) -> 0 | E8: =C8-D8 -> 0 | F8: =Dashboard!$C$2+SUM($E$4:E8) -> 500 | G8: =IF(E8<0,"Déficit","OK") -> OK
B9: =EOMONTH(TODAY(),-6)+1 -> 45992 | C9: =SUMIFS(MOVIMIENTOS!$H$6:$H$500,MOVIMIENTOS!$D$6:$D$500,"Ingreso",MOVIMIENTOS!$C$6:$C$500,">="&B9,MOVIMIENTOS!$C$6:$C$500,"<"&EDATE(B9,1)) -> 0 | D9: =SUMIFS(MOVIMIENTOS!$H$6:$H$500,MOVIMIENTOS!$D$6:$D$500,"Gasto",MOVIMIENTOS!$C$6:$C$500,">="&B9,MOVIMIENTOS!$C$6:$C$500,"<"&EDATE(B9,1)) -> 0 | E9: =C9-D9 -> 0 | F9: =Dashboard!$C$2+SUM($E$4:E9) -> 500 | G9: =IF(E9<0,"Déficit","OK") -> OK
B10: =EOMONTH(TODAY(),-5)+1 -> 46023 | C10: =SUMIFS(MOVIMIENTOS!$H$6:$H$500,MOVIMIENTOS!$D$6:$D$500,"Ingreso",MOVIMIENTOS!$C$6:$C$500,">="&B10,MOVIMIENTOS!$C$6:$C$500,"<"&EDATE(B10,1)) -> 0 | D10: =SUMIFS(MOVIMIENTOS!$H$6:$H$500,MOVIMIENTOS!$D$6:$D$500,"Gasto",MOVIMIENTOS!$C$6:$C$500,">="&B10,MOVIMIENTOS!$C$6:$C$500,"<"&EDATE(B10,1)) -> 0 | E10: =C10-D10 -> 0 | F10: =Dashboard!$C$2+SUM($E$4:E10) -> 500 | G10: =IF(E10<0,"Déficit","OK") -> OK
B11: =EOMONTH(TODAY(),-4)+1 -> 46054 | C11: =SUMIFS(MOVIMIENTOS!$H$6:$H$500,MOVIMIENTOS!$D$6:$D$500,"Ingreso",MOVIMIENTOS!$C$6:$C$500,">="&B11,MOVIMIENTOS!$C$6:$C$500,"<"&EDATE(B11,1)) -> 0 | D11: =SUMIFS(MOVIMIENTOS!$H$6:$H$500,MOVIMIENTOS!$D$6:$D$500,"Gasto",MOVIMIENTOS!$C$6:$C$500,">="&B11,MOVIMIENTOS!$C$6:$C$500,"<"&EDATE(B11,1)) -> 0 | E11: =C11-D11 -> 0 | F11: =Dashboard!$C$2+SUM($E$4:E11) -> 500 | G11: =IF(E11<0,"Déficit","OK") -> OK
B12: =EOMONTH(TODAY(),-3)+1 -> 46082 | C12: =SUMIFS(MOVIMIENTOS!$H$6:$H$500,MOVIMIENTOS!$D$6:$D$500,"Ingreso",MOVIMIENTOS!$C$6:$C$500,">="&B12,MOVIMIENTOS!$C$6:$C$500,"<"&EDATE(B12,1)) -> 0 | D12: =SUMIFS(MOVIMIENTOS!$H$6:$H$500,MOVIMIENTOS!$D$6:$D$500,"Gasto",MOVIMIENTOS!$C$6:$C$500,">="&B12,MOVIMIENTOS!$C$6:$C$500,"<"&EDATE(B12,1)) -> 0 | E12: =C12-D12 -> 0 | F12: =Dashboard!$C$2+SUM($E$4:E12) -> 500 | G12: =IF(E12<0,"Déficit","OK") -> OK
B13: =EOMONTH(TODAY(),-2)+1 -> 46113 | C13: =SUMIFS(MOVIMIENTOS!$H$6:$H$500,MOVIMIENTOS!$D$6:$D$500,"Ingreso",MOVIMIENTOS!$C$6:$C$500,">="&B13,MOVIMIENTOS!$C$6:$C$500,"<"&EDATE(B13,1)) -> 2000 | D13: =SUMIFS(MOVIMIENTOS!$H$6:$H$500,MOVIMIENTOS!$D$6:$D$500,"Gasto",MOVIMIENTOS!$C$6:$C$500,">="&B13,MOVIMIENTOS!$C$6:$C$500,"<"&EDATE(B13,1)) -> 631.4 | E13: =C13-D13 -> 1368.6 | F13: =Dashboard!$C$2+SUM($E$4:E13) -> 1868.6 | G13: =IF(E13<0,"Déficit","OK") -> OK
B14: =EOMONTH(TODAY(),-1)+1 -> 46143 | C14: =SUMIFS(MOVIMIENTOS!$H$6:$H$500,MOVIMIENTOS!$D$6:$D$500,"Ingreso",MOVIMIENTOS!$C$6:$C$500,">="&B14,MOVIMIENTOS!$C$6:$C$500,"<"&EDATE(B14,1)) -> 0 | D14: =SUMIFS(MOVIMIENTOS!$H$6:$H$500,MOVIMIENTOS!$D$6:$D$500,"Gasto",MOVIMIENTOS!$C$6:$C$500,">="&B14,MOVIMIENTOS!$C$6:$C$500,"<"&EDATE(B14,1)) -> 651.5 | E14: =C14-D14 -> -651.5 | F14: =Dashboard!$C$2+SUM($E$4:E14) -> 1217.1 | G14: =IF(E14<0,"Déficit","OK") -> Déficit
B15: =EOMONTH(TODAY(),0)+1 -> 46174 | C15: =SUMIFS(MOVIMIENTOS!$H$6:$H$500,MOVIMIENTOS!$D$6:$D$500,"Ingreso",MOVIMIENTOS!$C$6:$C$500,">="&B15,MOVIMIENTOS!$C$6:$C$500,"<"&EDATE(B15,1)) -> 0 | D15: =SUMIFS(MOVIMIENTOS!$H$6:$H$500,MOVIMIENTOS!$D$6:$D$500,"Gasto",MOVIMIENTOS!$C$6:$C$500,">="&B15,MOVIMIENTOS!$C$6:$C$500,"<"&EDATE(B15,1)) -> 0 | E15: =C15-D15 -> 0 | F15: =Dashboard!$C$2+SUM($E$4:E15) -> 1217.1 | G15: =IF(E15<0,"Déficit","OK") -> OK

Sheet DEUDAS
A1: CONTROL DE DEUDAS
B3: Acreedor | C3: Nivel | D3: Tipo | E3: Total deuda | F3: Cuota mensual | G3: Día pago | H3: Moneda | I3: Estado | J3: Pagado acum. | K3: Saldo pendiente
B4: BBVA | C4: 1 - Crítica | D4: Tarjeta | E4: 500 | F4: 500 | G4: 15 | H4: S/ | I4: Pendiente | J4: 0 | K4: =IFERROR(E4-J4,0) -> 500
B5: Mi Banco | C5: 1 - Crítica | D5: Préstamo | E5: 9500 | F5: 0 | G5: 15 | H5: S/ | I5: Pendiente | J5: 0 | K5: =IFERROR(E5-J5,0) -> 9500
B6: Olinda Bravo | C6: 2 - Familiar | D6: Personal | E6: 0 | F6: 400 | G6: 0 | H6: S/ | I6: Pendiente | J6: 0 | K6: =IFERROR(E6-J6,0) -> 0
B7: Jose Cotrina | C7: 2 - Familiar | D7: Personal | E7: 0 | F7: 500 | G7: 0 | H7: S/ | I7: Pendiente | J7: 0 | K7: =IFERROR(E7-J7,0) -> 0
B8: More Mendoza | C8: 3 - Sin interés | D8: Personal | E8: 2000 | F8: 0 | G8: 0 | H8: S/ | I8: Pendiente | J8: 0 | K8: =IFERROR(E8-J8,0) -> 2000
B9: Juan Bravo - Minivan | C9: 3 - Sin interés | D9: Vehículo | E9: 12000 | F9: 0 | G9: 0 | H9: S/ | I9: Pendiente | J9: 0 | K9: =IFERROR(E9-J9,0) -> 12000
B10: Elvi Bravo | C10: 3 - Sin interés | D10: Personal | E10: 4000 | F10: 0 | G10: 0 | H10: S/ | I10: Pendiente | J10: 0 | K10: =IFERROR(E10-J10,0) -> 4000
B11: David Portilla | C11: 3 - Sin interés | D11: Personal | E11: 6000 | F11: 0 | G11: 0 | H11: S/ | I11: Pendiente | J11: 0 | K11: =IFERROR(E11-J11,0) -> 6000
B12: Tarjeta viaje | C12: 1 - Crítica | D12: Tarjeta USD | E12: 500 | F12: 0 | G12: 0 | H12: USD | I12: Pendiente | J12: 0 | K12: =IFERROR(E12-J12,0) -> 500
B13: TOTAL | E13: =SUM(E4:E12) -> 34500 | F13: =SUM(F4:F12) -> 1400 | J13: =SUM(J4:J12) -> 0 | K13: =SUM(K4:K12) -> 34500

Sheet CONTROL PERSONAL
A1: CONTROL PERSONAL - HÁBITOS Y DECISIONES
B3: Fecha | C3: Sueño | D3: Entrenamiento | E3: Estudio | F3: Trabajo clave | G3: Gasto impulsivo | H3: Comentario

Sheet LISTAS
A1: LISTAS MAESTRAS - FINANZAS PERSONALES
A3: Categoría | B3: Subcategoría | D3: Tipo | F3: Medio de pago | H3: Estado deuda | J3: Categorías únicas
A4: Alimentación | B4: Desayuno | D4: Ingreso | F4: Efectivo | H4: Pendiente | J4: Alimentación
A5: Alimentación | B5: Almuerzo | D5: Gasto | F5: Yape / Plin | H5: Pagado | J5: Vivienda
A6: Alimentación | B6: Cena | F6: Tarjeta débito | H6: Parcial | J6: Transporte
A7: Alimentación | B7: Snacks / Golosinas | F7: Tarjeta crédito | H7: Vencido | J7: Vehículo
A8: Alimentación | B8: Café | F8: Transferencia | J8: Deuda
A9: Alimentación | B9: Delivery | J9: Salud
A10: Alimentación | B10: Restaurante | J10: Cuidado Personal
A11: Alimentación | B11: Supermercado | J11: Indumentaria
A12: Alimentación | B12: Agua / Bebidas | J12: Educación
A13: Alimentación | B13: Otros alimentación | J13: Trabajo / Negocio
A14: Vivienda | B14: Alquiler | J14: Ocio
A15: Vivienda | B15: Luz | J15: Ingresos
A16: Vivienda | B16: Agua | J16: Otros
A17: Vivienda | B17: Internet
A18: Vivienda | B18: Gas
A19: Vivienda | B19: Mantenimiento hogar
A20: Vivienda | B20: Equipamiento hogar
A21: Vivienda | B21: Otros vivienda
A22: Transporte | B22: Pasaje público
A23: Transporte | B23: Taxi / Indriver
A24: Transporte | B24: Peajes
A25: Transporte | B25: Estacionamiento
A26: Transporte | B26: Otros transporte
A27: Vehículo | B27: Combustible
A28: Vehículo | B28: Mantenimiento preventivo
... A93: Otros | B93: Otros

Sheet PRESUPUESTO
A1: PRESUPUESTO MENSUAL
B3: Categoría | C3: Límite mensual | D3: Prioridad | E3: Notas
B4: Alimentación | C4: 600 | E4: Ajustar según realidad mensual
B5: Vivienda | C5: 550 | E5: Ajustar según realidad mensual
B6: Transporte | C6: 0 | E6: Ajustar según realidad mensual
B7: Vehículo | C7: 0 | E7: Ajustar según realidad mensual
B8: Deuda | C8: 1300 | E8: Ajustar según realidad mensual
B9: Salud | C9: 0 | E9: Ajustar según realidad mensual
B10: Cuidado Personal | C10: 0 | E10: Ajustar según realidad mensual
B11: Indumentaria | C11: 0 | E11: Ajustar según realidad mensual
B12: Educación | C12: 0 | E12: Ajustar según realidad mensual
B13: Trabajo / Negocio | C13: 0 | E13: Ajustar según realidad mensual
B14: Ocio | C14: 0 | E14: Ajustar según realidad mensual
B15: Ingresos | C15: 0 | E15: Ajustar según realidad mensual
B16: Otros | C16: 0 | E16: Ajustar según realidad mensual
B17: TOTAL PRESUPUESTO | C17: =SUM(C4:C16) -> 2450
